<mujoco model="4leg">

  <!-- <this is default part> -->
  <asset>
      <texture builtin="gradient" height="100" rgb1="1 1 1" rgb2="0 0 0" type="skybox" width="100"/>
      <texture builtin="flat" height="1278" mark="cross" markrgb="1 1 1" name="texgeom" random="0.01" rgb1="0.8 0.6 0.2" rgb2="0.8 0.6 0.2" type="cube" width="127"/>
      <texture builtin="checker" height="100" name="texplane" rgb1="0 0 0" rgb2="0.8 0.8 0.8" type="2d" width="100"/>
      <material name="MatPlane" reflectance="0.5" shininess="1" specular="1" texrepeat="60 60" texture="texplane"/>
      <material name="geom" texture="texgeom" texuniform="true"/>
  </asset>

  <!-- <this is physics part - is very important> -->
          
  <default>
      <joint armature="0.001" damping=".01" />
      <geom density="1.5" conaffinity="1" condim="3" contype="1" friction=".5 .5 .5" rgba="0.8 0.6 .4 1" solimp="0.9 0.95 0.001" solref="0.02 1"/>
  </default>
  <option gravity="0 0 -9.81" iterations="50" tolerance="1e-10" solver="Newton" jacobian="dense" cone="pyramidal" noslip_iterations="3" />
  <size nconmax="50" njmax="200" nstack="10000"/>
  <compiler angle="radian" coordinate="local" inertiafromgeom="true" />

  <!-- <this is world body part> -->

  <worldbody>
    <light cutoff="100" diffuse="1 1 1" dir="-0 0 -1.3" directional="true" exponent="1" pos="0 0 1.3" specular=".1 .1 .1"/>
    <geom conaffinity="1" condim="3" material="MatPlane" name="floor" pos="0 0 0" rgba="0.8 0.9 0.8 1" size="40 40 10" type="plane"/>
    <!-- world body defult part -->

    <body name="spine" pos="0 0 1" >
    <camera name="track" mode="trackcom" pos="0 -3 0.3" xyaxes="1 0 0 0 0 1"/>
      <geom name ="spine" type="box" size="0.75 0.5 0.05"/>
      <!-- <geom name ="body" type="box" pos = "0 0 0.1" size="0.6 0.4 0.1"/> -->
      <joint name="pos_x"  pos="0 0 0" type="slide" axis="1 0 0"/>
      <joint name="pos_y"  pos="0 0 0" type="slide" axis="0 1 0"/>
      <joint name="pos_z"  pos="0 0 0" type="slide" axis="0 0 1"/>

      <joint name="rot"  pos="0 0 0" type="ball"/>
      <!-- <joint name="rot_x"  pos="0 0 0" type="hinge" axis="1 0 0"/>
      <joint name="rot_y"  pos="0 0 0" type="hinge" axis="0 1 0"/>
      <joint name="rot_z"  pos="0 0 0" type="hinge" axis="0 0 1"/> -->

      <!-- -35 degree : -0.611 -->  
      <!-- 125 degree : 2.182 -->   
      <!-- 80 degree : 1.396 -->    
      <body name="frontrightleg" pos="0.72 0.5 0">
        <joint  name="frontrightleg1"  pos="0 0.01 0"   range="-0.611 2.182" type="hinge" axis="0 1 0" limited = "true"/>
        <geom name="frontrightleg" pos="0.25 0.06 -.25" euler = "0 -0.78539 0" size="0.05 0.05 0.35" type="box"/>
        <body pos=".5 0.17 -.5">
          <joint name="frontrightleg2" pos="0 0 0"      range="-1.396 1.396" type="hinge" axis="0 1 0" limited = "true"/>
          <geom pos="-0.25 0.01 -.25" euler = "0 0.78539 0" size="0.05 0.05 .4" type="box"/>
        </body>
      </body>
    
      <body name="frontleftleg" pos="0.72 -0.5 0">
        <joint  name="frontleftleg1"  pos="0 -0.01 0"   range="-0.611 2.182" type="hinge" axis="0 1 0" limited = "true"/>
        <geom name="frontleftleg" pos="0.25 -0.06 -.25" euler = "0 -0.78539 0" size="0.05 0.05 0.35" type="box"/>
        <body pos=".5 -0.17 -.5">
          <joint name="frontleftleg2" pos="0 0 0"      range="-1.396 1.396" type="hinge" axis="0 1 0" limited = "true"/>
          <geom pos="-0.25 -0.01 -.25" euler = "0 0.78539 0" size="0.05 0.05 .4" type="box"/>
        </body>
      </body>

      <body name="backrightleg" pos="-0.72 0.5 0">
        <joint  name="backrightleg1"  pos="0 0.01 0"   range="-2.182 0.611" type="hinge" axis="0 1 0" limited = "true"/>
        <geom pos="-0.25 0.06 -.25" euler = "0 0.78539 0" size="0.05 0.05 0.35" type="box"/>
        <body pos="-.5 0.17 -.5">
          <joint name="backrightleg2" pos="0 0 0"      range="-1.396 1.396" type="hinge" axis="0 1 0" limited = "true"/>
          <geom pos="0.25 0.01 -.25" euler = "0 -0.78539 0" size="0.05 0.05 .4" type="box"/>
        </body>
      </body>
      
      <body name="backleftleg" pos="-0.72 -0.5 0">
        <joint  name="backleftleg1"  pos="0 -0.01 0"   range="-2.182 0.611" type="hinge" axis="0 1 0" limited = "true"/>
        <geom name="backleftleg" pos="-0.25 -0.06 -.25" euler = "0 0.78539 0" size="0.05 0.05 0.35" type="box"/>
        <body pos="-.5 -0.17 -.5">
          <joint name="backleftleg2" pos="0 0 0"      range="-1.396 1.396" type="hinge" axis="0 1 0" limited = "true"/>
          <geom pos="0.25 -0.01 -.25" euler = "0 -0.78539 0" size="0.05 0.05 .4" type="box"/>
        </body>
      </body>
    
    </body>

  </worldbody>





  <!-- <this is actuator part> -->

  <actuator>
      <motor joint="frontrightleg1"  ctrlrange ="-1.8 1.8" forcelimited="true" forcerange="-1.8 1.8"/>
      <motor joint="frontrightleg2"  ctrlrange ="-1.8 1.8" forcelimited="true" forcerange="-1.8 1.8"/>

      <motor joint="frontleftleg1"   ctrlrange ="-1.8 1.8" forcelimited="true" forcerange="-1.8 1.8"/>
      <motor joint="frontleftleg2"   ctrlrange ="-1.8 1.8" forcelimited="true" forcerange="-1.8 1.8"/>

      <motor joint="backrightleg1"   ctrlrange ="-1.8 1.8" forcelimited="true" forcerange="-1.8 1.8"/>
      <motor joint="backrightleg2"   ctrlrange ="-1.8 1.8" forcelimited="true" forcerange="-1.8 1.8"/>

      <motor joint="backleftleg1"    ctrlrange ="-1.8 1.8" forcelimited="true" forcerange="-1.8 1.8"/>
      <motor joint="backleftleg2"    ctrlrange ="-1.8 1.8" forcelimited="true" forcerange="-1.8 1.8"/>

  </actuator>

</mujoco>
