<mujoco model="ball_model">
    <compiler angle ="degree"/>

    <default>
        <!-- <joint limited="true"/> -->
        <!-- <joint damping= ".01" solimplimit="0 .8 .3" solreflimit=".02 1" stiffness="8"/> -->
        <joint damping= "5"/>
        <geom conaffinity="1" condim = "3"/>
    </default>

    <!-- 텍스처와 재질 정의 -->
    <asset>
        <texture builtin="gradient" height="100" rgb1="1 1 1" rgb2="0 0 0" type="skybox" width="100"/>
        <texture builtin="flat" height="1278" mark="cross" markrgb="1 1 1" name="texgeom" random="0.01" rgb1="0.8 0.6 0.4" rgb2="0.8 0.6 0.4" type="cube" width="127"/>
        <texture builtin="checker" height="100" name="texplane" rgb1="0 0 0" rgb2="0.8 0.8 0.8" type="2d" width="100"/>
        <material name="MatPlane" reflectance="0.5" shininess="1" specular="1" texrepeat="60 60" texture="texplane"/>
        <material name="geom" texture="texgeom" texuniform="true"/>
    </asset>
    <option gravity="0 0 -9.8"/>

    <worldbody>
        <!-- 조명 pos 위치 dir 방향 diffuse 확산광(빛이 고르게 퍼지도록 ) specular 반사광 ambient 주변(주변이 밝아지도록)-->
        <light cutoff="100" diffuse="1 1 1" dir="-0 0 -1.3" directional="true" exponent="1" pos="0 0 1.3" specular=".1 .1 .1"/>
        <geom conaffinity="1" condim="3" material="MatPlane" name="floor" pos="0 0 0" rgba="0.8 0.9 0.8 1" size="40 40 40" type="plane"/>
        <!-- if you want to move the box, then the box should need joint-->
        <body name = "box2" pos="0 0 2.3" euler = "0 0 0">
            <joint name = "target"  type="free" />
            <geom type="sphere" size=".1 .1 .1" rgba = "0.9 0 0.1 1"/>
            <inertial pos="0 0 0" mass="1" diaginertia="1 1 1"/>
        </body>

        <body name ="asdf" pos="0 0 1.5" euler = "0 0 0">
            <joint name = "joint1"  type="hinge" axis="1 0 0" range="-40 40" limited="true"/>
            <joint name = "joint2"  type="hinge" axis="0 1 0" range="-40 40" limited="true"/>
            <geom name = "box1" type="box" size=".3 .3 .3" rgba = "0.9 0 0.1 1"/>
            <inertial pos="0 0 0" mass="10" diaginertia="0.01 0.01 0.01"/>
        </body>
        

        <!-- but only the header have the free joint then byproducts move along the header-->
        

    </worldbody>

    <actuator>
        <position joint="joint1" kp="50" gear="1" ctrllimited="true" ctrlrange="-40 40"/>
        <position joint="joint2" kp="50" gear="1" ctrllimited="true" ctrlrange="-40 40"/>

        <!-- <motor joint="joint1" axis="0 1 0"/> -->
    </actuator>    
</mujoco>