<mujoco model="ball_model">

            
    <default>
        <!-- <joint  damping=".01" limited="true" solimplimit="0 .8 .03" solreflimit=".02 1" stiffness="8"/> -->
        <joint armature="0.001" damping=".01" />
        <geom density="0.05" conaffinity="1" condim="3" contype="1" friction=".4 .1 .1" rgba="0.8 0.6 .4 1" solimp="0.0 0.8 0.01" solref="0.02 1"/>
        <!-- <motor ctrllimited="true" ctrlrange="-1 1"/> -->
    </default>
    <option  iterations="50" tolerance="1e-10" solver="Newton" jacobian="dense" cone="pyramidal"/>
        <option noslip_iterations="3"/>

    <size nconmax="50" njmax="200" nstack="10000"/>

    <compiler angle="degree" coordinate="local" inertiafromgeom="true" />

    <!-- 텍스처와 재질 정의 -->
    <asset>
        <texture builtin="gradient" height="100" rgb1="1 1 1" rgb2="0 0 0" type="skybox" width="100"/>
        <texture builtin="flat" height="1278" mark="cross" markrgb="1 1 1" name="texgeom" random="0.01" rgb1="0.8 0.6 0.4" rgb2="0.8 0.6 0.4" type="cube" width="127"/>
        <texture builtin="checker" height="100" name="texplane" rgb1="0 0 0" rgb2="0.8 0.8 0.8" type="2d" width="100"/>
        <material name="MatPlane" reflectance="0.5" shininess="1" specular="1" texrepeat="60 60" texture="texplane"/>
        <material name="geom" texture="texgeom" texuniform="true"/>
    </asset>
    <option gravity="0 0 -9.8"/>

    <worldbody>
        <!-- 조명 pos 위치 dir 방향 diffuse 확산광(빛이 고르게 퍼지도록 ) specular 반사광 ambient 주변(주변이 밝아지도록)-->
        <light cutoff="100" diffuse="1 1 1" dir="-0 0 -1.3" directional="true" exponent="1" pos="0 0 1.3" specular=".1 .1 .1"/>
        <geom conaffinity="1" condim="3" material="MatPlane" name="floor" pos="0 0 0" rgba="0.8 0.9 0.8 1" size="40 40 40" type="plane"/>
        <!-- if you want to move the box, then the box should need joint-->
        
        <body name = "box2" pos="0 0 0" euler = "0 0 0">
            <joint name = "target"  type="free" />
            <geom type="sphere" size=".1 .1 .1" rgba = "0.9 0 0.1 1"/>
            <inertial pos="0 0 0" mass="1" diaginertia="1 1 1"/>
        </body>

        <body name ="asdf" pos="0 5 .3" euler = "0 0 0">
            <joint name = "joint1"  type="slide" axis="1 0 0"   />
            <geom name = "box1" type="box" size=".1 .1 .1" rgba = "0.9 0 0.1 1"/>
            <inertial pos="0 0 0" mass="2" diaginertia=".01 .01 .01"/>
        </body>

        <body name ="asdf2" pos="0 0 1" euler = "0 0 0">
            <joint name = "joint2"  type="hinge" axis="1 0 0"   />
            <joint name = "joint3"  type="hinge" axis="0 1 0"   />
            <joint name = "joint4"  type="hinge" axis="0 0 1"   />
            <geom name = "box2" type="box" size=".1 .5 .1" rgba = "0.9 0 0.1 1"/>
            <body name ="asdf4" pos="0 0 1" euler = "0 0 0">
                <joint name = "joint5"  type="hinge" axis="0 0 1"   />
                <geom name = "box4" type="box" size="0.1 0.1 .2" rgba = "0.9 0 0.1 1"/>
            </body>
        </body>

        <!-- <body name ="asdf3" pos=".5 0 1" euler = "0 0 0">
            <geom name = "box3" type="box" size=".1 .5 .1" rgba = "0.9 0 0.1 1"/>
        </body> -->
        <!-- but only the header have the free joint then byproducts move along the header-->
        

    </worldbody>

    <actuator>
        <motor joint="joint2" />
        <motor joint="joint3" />
    
        <!-- <motor joint="joint1" axis="0 1 0"/> -->
    </actuator>    
</mujoco>